Workbook

Sheet Sheet1
A1: Order_ID | B1: Order_Date | C1: Customer_ID | D1: Product | E1: Category | F1: Quantity | G1: Unit_Price | H1: Discount_% | I1: Sales | J1: Profit | K1: Country | L1: Payment_Method
A2: ORD001 | B2: 45327 | C2: CUST18 | D2: Mouse | E2: Accessories | F2: -1 | G2: 2139 | H2: 10 | I2: -1925.1 | J2: 3.93 | K2: India | L2: UPI
A3: ORD002 | B3: 45342 | C3: CUST18 | D3: Phone | E3: Electronics | F3: 1 | G3: 33618 | H3: 20 | I3: 26894.4 | J3: -2403.97 | K3: UK | L3: UPI
A4: ORD003 | B4: 45378 | C4: CUST13 | D4: Phone | E4: Electronics | F4: 4 | G4: 22798 | H4: 10 | I4: 82072.8 | J4: -3103.02 | K4: UK | L4: UPI
A5: ORD004 | B5: 45388 | C5: CUST10 | D5: Mouse | E5: Accessories | F5: 5 | G5: 35642 | H5: 0 | I5: 178210 | J5: 51546.58 | K5: UK | L5: Credit Card
A6: ORD005 | B6: 45312 | C6: CUST4 | D6: Mouse | E6: Accessories | F6: -1 | G6: 3503 | H6: 5 | I6: -3327.85 | J6: -696.28 | K6: UK | L6: Credit Card
A7: ORD006 | B7: 45466 | C7: CUST20 | D7: Headphones | E7: Accessories | F7: 3 | G7: 14230 | H7: 10 | I7: 38421 | J7: 6943.76 | K7: USA | L7: Credit Card
A8: ORD007 | B8: 45375 | C8: CUST2 | D8: Keyboard | E8: Accessories | G8: 18191 | H8: 20 | I8: 58211.2 | J8: -707.49 | K8: UK | L8: Net Banking
A9: ORD008 | B9: 45372 | C9: CUST16 | D9: Headphones | E9: Accessories | F9: -1 | G9: 14326 | H9: 20 | I9: -11460.8 | J9: -2871.47 | K9: Canada | L9: Credit Card
A10: ORD009 | B10: 45441 | C10: CUST19 | D10: Headphones | E10: Accessories | F10: 0 | G10: 16662 | H10: 20 | I10: 0 | J10: 0 | K10: USA | L10: Net Banking
A11: ORD010 | B11: 45466 | C11: CUST3 | D11: Laptop | E11: Electronics | F11: -2 | G11: 7685 | H11: 5 | I11: -14601.5 | J11: -2204.51 | K11: Canada | L11: Debit Card
A12: ORD011 | B12: 45429 | C12: CUST11 | D12: Monitor | E12: Electronics | F12: -2 | G12: 45083 | H12: 0 | I12: -90166 | J12: -15570.24 | K12: Canada | L12: UPI
A13: ORD012 | B13: 45319 | C13: CUST10 | D13: Mouse | E13: Accessories | F13: 2 | G13: 33306 | H13: 5 | I13: 63281.4 | J13: 6522.58 | K13: USA | L13: Credit Card
A14: ORD013 | B14: 45445 | C14: CUST1 | D14: Headphones | E14: Accessories | F14: 0 | G14: 35848 | H14: 20 | I14: 0 | J14: 0 | K14: UK | L14: Credit Card
A15: ORD014 | B15: 45416 | C15: CUST18 | D15: Laptop | E15: Electronics | F15: 1 | G15: 37682 | H15: 0 | I15: 37682 | J15: -2477.16 | K15: Canada | L15: Credit Card
A16: ORD015 | B16: 45468 | C16: CUST10 | D16: Headphones | E16: Accessories | F16: 4 | G16: 14380 | H16: 20 | I16: 46016 | J16: 9300.11 | K16: UK | L16: Net Banking
A17: ORD016 | B17: wrong_date | C17: CUST18 | D17: Monitor | E17: Electronics | F17: 5 | G17: 8430 | H17: 5 | I17: 40042.5 | J17: -405.27 | K17: India | L17: UPI
A18: ORD017 | B18: 45352 | C18: CUST16 | D18: Phone | E18: Electronics | F18: -1 | G18: 2558 | H18: 10 | I18: -2302.2 | J18: 164.97 | K18: Canada | L18: Credit Card
A19: ORD018 | B19: 45402 | C19: CUST14 | D19: Keyboard | E19: Accessories | F19: 4 | G19: 12978 | H19: 0 | I19: 51912 | J19: -3178.45 | K19: India | L19: UPI
A20: ORD019 | B20: 45429 | C20: CUST14 | D20: Keyboard | E20: Accessories | F20: 3 | G20: 7661 | H20: 5 | I20: 21833.85 | J20: -510.13 | K20: India | L20: Net Banking
A21: ORD020 | B21: 45315 | C21: CUST8 | D21: Monitor | E21: Electronics | F21: -1 | G21: 3815 | H21: 20 | I21: -3052 | J21: -715.42 | K21: USA | L21: Net Banking
A22: ORD021 | B22: 45359 | C22: CUST15 | D22: Laptop | E22: Electronics | F22: 0 | G22: 25336 | H22: 0 | I22: 0 | J22: 0 | K22: Canada | L22: Credit Card
A23: ORD022 | B23: 45430 | C23: CUST11 | D23: Phone | E23: Electronics | F23: 2 | G23: 14767 | H23: 0 | I23: 29534 | J23: 3888.8 | K23: USA | L23: UPI
A24: ORD023 | B24: 45464 | C24: CUST13 | D24: Monitor | E24: Electronics | F24: -1 | G24: 12678 | H24: 0 | I24: -12678 | J24: -1749.74 | K24: USA | L24: UPI
A25: ORD024 | B25: 45372 | C25: CUST7 | D25: Monitor | E25: Electronics | F25: -1 | G25: 27974 | H25: 20 | I25: -22379.2 | J25: -2821.81 | K25: UK | L25: Net Banking
A26: ORD025 | B26: wrong_date | C26: CUST20 | D26: Phone | E26: Electronics | F26: 2 | G26: 30464 | H26: 10 | I26: 54835.2 | J26: 14893.64 | K26: India | L26: Credit Card
A27: ORD026 | B27: 45354 | C27: CUST6 | D27: Monitor | E27: Electronics | F27: 2 | G27: 9180 | H27: 10 | I27: 16524 | J27: 4169.76 | K27: UK | L27: UPI
A28: ORD027 | B28: 45326 | C28: CUST4 | D28: Mouse | E28: Accessories | F28: 2 | G28: 43975 | H28: 0 | I28: 87950 | J28: 24236.56 | K28: UK | L28: Credit Card
A29: ORD028 | B29: 45356 | C29: CUST2 | D29: Mouse | E29: Accessories | F29: 3 | G29: 13842 | H29: 10 | I29: 37373.4 | J29: 3818.2 | K29: UK | L29: UPI
A30: ORD029 | B30: 45405 | C30: CUST14 | D30: Laptop | E30: Electronics | F30: 3 | G30: 9073 | H30: 10 | I30: 24497.1 | J30: -866.39 | K30: USA | L30: UPI
A31: ORD030 | B31: 45385 | C31: CUST2 | D31: Headphones | E31: Accessories | F31: 0 | G31: 28666 | H31: 5 | I31: 0 | J31: 0 | K31: USA | L31: UPI
A32: ORD031 | B32: 45352 | C32: CUST6 | D32: Headphones | E32: Accessories | G32: 41175 | H32: 5 | I32: 156465 | J32: 42293.35 | K32: UK | L32: Net Banking
A33: ORD032 | B33: 45319 | C33: CUST2 | D33: Mouse | E33: Accessories | F33: 1 | G33: 17985 | H33: 5 | I33: 17085.75 | J33: 3672.58 | K33: Canada | L33: Debit Card
A34: ORD033 | B34: 45394 | C34: CUST3 | D34: Headphones | E34: Accessories | F34: 1 | G34: 15109 | H34: 0 | I34: 15109 | J34: 2478.08 | K34: Canada | L34: Debit Card
A35: ORD034 | B35: wrong_date | C35: CUST20 | D35: Laptop | E35: Electronics | F35: -1 | G35: 17618 | H35: 5 | I35: -16737.1 | J35: -2213.25 | K35: UK | L35: Net Banking
A36: ORD035 | B36: 45303 | C36: CUST1 | D36: Monitor | E36: Electronics | F36: -1 | G36: 25744 | H36: 20 | I36: -20595.2 | J36: 493.64 | K36: USA | L36: Debit Card
A37: ORD036 | B37: 45461 | C37: CUST10 | D37: Keyboard | E37: Accessories | F37: -1 | G37: 44031 | H37: 10 | I37: -39627.9 | J37: -5914.95 | K37: UK | L37: Net Banking
A38: ORD037 | B38: 45462 | C38: CUST6 | D38: Mouse | E38: Accessories | F38: 2 | G38: 36833 | H38: 5 | I38: 69982.7 | J38: -1628.07 | K38: India | L38: Debit Card
A39: ORD038 | B39: 45374 | C39: CUST15 | D39: Headphones | E39: Accessories | F39: 1 | G39: 28673 | H39: 20 | I39: 22938.4 | J39: 3272.5 | K39: USA | L39: UPI
A40: ORD039 | B40: 45349 | C40: CUST5 | D40: Headphones | E40: Eletronics | F40: 3 | G40: 6620 | H40: 5 | I40: 18867 | J40: 3190.75 | K40: Canada | L40: UPI
...

Sheet Cleaned_Data
A1: Order_ID | B1: Order_Date | C1: Customer_ID | D1: Product | E1: Category | F1: Quantity | G1: Unit_Price | H1: Discount_% | I1: Sales | J1: Profit | K1: Country | L1: Payment_Method | M1: Year | N1: Month | O1: Profit_Margin | P1: Month Column | Q1: Year Column | R1: Profit % Column | S1: Net Sales Column
A2: ORD001 | B2: 45414 | C2: CUST18 | D2: Mouse | E2: Accessories | F2: -1 | G2: 2139 | H2: 10 | I2: -1925.1 | J2: 3.93 | K2: India | L2: UPI | M2: 2024 | N2: 5 | O2: -0.0020414524 | P2: =TEXT(Table1[[#This Row],[Order_Date]],"mmm") -> May | Q2: =YEAR(Table1[[#This Row],[Order_Date]]) -> 2024 | R2: =Table1[[#This Row],[Profit]]/Table1[[#This Row],[Sales]] -> -0.0020414524 | S2: =IF(I2<0,0,I2) -> 0
A3: ORD002 | B3: 45342 | C3: CUST18 | D3: Phone | E3: Electronics | F3: 1 | G3: 33618 | H3: 20 | I3: 26894.4 | J3: -2403.97 | K3: UK | L3: UPI | M3: 2024 | N3: 2 | O3: -0.089385523 | P3: =TEXT(Table1[[#This Row],[Order_Date]],"mmm") -> Feb | Q3: =YEAR(Table1[[#This Row],[Order_Date]]) -> 2024 | R3: =Table1[[#This Row],[Profit]]/Table1[[#This Row],[Sales]] -> -0.089385523 | S3: =IF(I3<0,0,I3) -> 26894.4
A4: ORD003 | B4: 45378 | C4: CUST13 | D4: Phone | E4: Electronics | F4: 4 | G4: 22798 | H4: 10 | I4: 82072.8 | J4: -3103.02 | K4: UK | L4: UPI | M4: 2024 | N4: 3 | O4: -0.037808141 | P4: =TEXT(Table1[[#This Row],[Order_Date]],"mmm") -> Mar | Q4: =YEAR(Table1[[#This Row],[Order_Date]]) -> 2024 | R4: =Table1[[#This Row],[Profit]]/Table1[[#This Row],[Sales]] -> -0.037808141 | S4: =IF(I4<0,0,I4) -> 82072.8
A5: ORD004 | B5: 45447 | C5: CUST10 | D5: Mouse | E5: Accessories | F5: 5 | G5: 35642 | H5: 0 | I5: 178210 | J5: 51546.58 | K5: UK | L5: Credit Card | M5: 2024 | N5: 6 | O5: 0.28924628247573086 | P5: =TEXT(Table1[[#This Row],[Order_Date]],"mmm") -> Jun | Q5: =YEAR(Table1[[#This Row],[Order_Date]]) -> 2024 | R5: =Table1[[#This Row],[Profit]]/Table1[[#This Row],[Sales]] -> 0.28924628 | S5: =IF(I5<0,0,I5) -> 178210
A6: ORD005 | B6: 45312 | C6: CUST4 | D6: Mouse | E6: Accessories | F6: -1 | G6: 3503 | H6: 5 | I6: -3327.85 | J6: -696.28 | K6: UK | L6: Credit Card | M6: 2024 | N6: 1 | O6: 0.20922818035668675 | P6: =TEXT(Table1[[#This Row],[Order_Date]],"mmm") -> Jan | Q6: =YEAR(Table1[[#This Row],[Order_Date]]) -> 2024 | R6: =Table1[[#This Row],[Profit]]/Table1[[#This Row],[Sales]] -> 0.20922818 | S6: =IF(I6<0,0,I6) -> 0
A7: ORD006 | B7: 45466 | C7: CUST20 | D7: Headphones | E7: Accessories | F7: 3 | G7: 14230 | H7: 10 | I7: 38421 | J7: 6943.76 | K7: USA | L7: Credit Card | M7: 2024 | N7: 6 | O7: 0.1807282475729419 | P7: =TEXT(Table1[[#This Row],[Order_Date]],"mmm") -> Jun | Q7: =YEAR(Table1[[#This Row],[Order_Date]]) -> 2024 | R7: =Table1[[#This Row],[Profit]]/Table1[[#This Row],[Sales]] -> 0.18072825 | S7: =IF(I7<0,0,I7) -> 38421
A8: ORD007 | B8: 45375 | C8: CUST2 | D8: Keyboard | E8: Accessories | F8: 1 | G8: 18191 | H8: 20 | I8: 58211.2 | J8: -707.49 | K8: UK | L8: Net Banking | M8: 2024 | N8: 3 | O8: -0.012153847 | P8: =TEXT(Table1[[#This Row],[Order_Date]],"mmm") -> Mar | Q8: =YEAR(Table1[[#This Row],[Order_Date]]) -> 2024 | R8: =Table1[[#This Row],[Profit]]/Table1[[#This Row],[Sales]] -> -0.012153847 | S8: =IF(I8<0,0,I8) -> 58211.2
A9: ORD008 | B9: 45372 | C9: CUST16 | D9: Headphones | E9: Accessories | F9: -1 | G9: 14326 | H9: 20 | I9: -11460.8 | J9: -2871.47 | K9: Canada | L9: Credit Card | M9: 2024 | N9: 3 | O9: 0.2505470822281167 | P9: =TEXT(Table1[[#This Row],[Order_Date]],"mmm") -> Mar | Q9: =YEAR(Table1[[#This Row],[Order_Date]]) -> 2024 | R9: =Table1[[#This Row],[Profit]]/Table1[[#This Row],[Sales]] -> 0.25054708 | S9: =IF(I9<0,0,I9) -> 0
A10: ORD009 | B10: 45441 | C10: CUST19 | D10: Headphones | E10: Accessories | F10: 0 | G10: 16662 | H10: 20 | I10: 0 | J10: 0 | K10: USA | L10: Net Banking | M10: 2024 | N10: 5 | P10: =TEXT(Table1[[#This Row],[Order_Date]],"mmm") -> May | Q10: =YEAR(Table1[[#This Row],[Order_Date]]) -> 2024 | R10: =Table1[[#This Row],[Profit]]/Table1[[#This Row],[Sales]] -> #DIV/0! | S10: =IF(I10<0,0,I10) -> 0
A11: ORD010 | B11: 45466 | C11: CUST3 | D11: Laptop | E11: Electronics | F11: -2 | G11: 7685 | H11: 5 | I11: -14601.5 | J11: -2204.51 | K11: Canada | L11: Debit Card | M11: 2024 | N11: 6 | O11: 0.15097832414477966 | P11: =TEXT(Table1[[#This Row],[Order_Date]],"mmm") -> Jun | Q11: =YEAR(Table1[[#This Row],[Order_Date]]) -> 2024 | R11: =Table1[[#This Row],[Profit]]/Table1[[#This Row],[Sales]] -> 0.15097832 | S11: =IF(I11<0,0,I11) -> 0
A12: ORD011 | B12: 45429 | C12: CUST11 | D12: Monitor | E12: Electronics | F12: -2 | G12: 45083 | H12: 0 | I12: -90166 | J12: -15570.24 | K12: Canada | L12: UPI | M12: 2024 | N12: 5 | O12: 0.17268416032650888 | P12: =TEXT(Table1[[#This Row],[Order_Date]],"mmm") -> May | Q12: =YEAR(Table1[[#This Row],[Order_Date]]) -> 2024 | R12: =Table1[[#This Row],[Profit]]/Table1[[#This Row],[Sales]] -> 0.17268416 | S12: =IF(I12<0,0,I12) -> 0
A13: ORD012 | B13: 45319 | C13: CUST10 | D13: Mouse | E13: Accessories | F13: 2 | G13: 33306 | H13: 5 | I13: 63281.4 | J13: 6522.58 | K13: USA | L13: Credit Card | M13: 2024 | N13: 1 | O13: 0.10307262481550661 | P13: =TEXT(Table1[[#This Row],[Order_Date]],"mmm") -> Jan | Q13: =YEAR(Table1[[#This Row],[Order_Date]]) -> 2024 | R13: =Table1[[#This Row],[Profit]]/Table1[[#This Row],[Sales]] -> 0.10307262 | S13: =IF(I13<0,0,I13) -> 63281.4
A14: ORD013 | B14: 45328 | C14: CUST1 | D14: Headphones | E14: Accessories | F14: 0 | G14: 35848 | H14: 20 | I14: 0 | J14: 0 | K14: UK | L14: Credit Card | M14: 2024 | N14: 2 | P14: =TEXT(Table1[[#This Row],[Order_Date]],"mmm") -> Feb | Q14: =YEAR(Table1[[#This Row],[Order_Date]]) -> 2024 | R14: =Table1[[#This Row],[Profit]]/Table1[[#This Row],[Sales]] -> #DIV/0! | S14: =IF(I14<0,0,I14) -> 0
A15: ORD014 | B15: 45387 | C15: CUST18 | D15: Laptop | E15: Electronics | F15: 1 | G15: 37682 | H15: 0 | I15: 37682 | J15: -2477.16 | K15: Canada | L15: Credit Card | M15: 2024 | N15: 4 | O15: -0.065738549 | P15: =TEXT(Table1[[#This Row],[Order_Date]],"mmm") -> Apr | Q15: =YEAR(Table1[[#This Row],[Order_Date]]) -> 2024 | R15: =Table1[[#This Row],[Profit]]/Table1[[#This Row],[Sales]] -> -0.065738549 | S15: =IF(I15<0,0,I15) -> 37682
A16: ORD015 | B16: 45468 | C16: CUST10 | D16: Headphones | E16: Accessories | F16: 4 | G16: 14380 | H16: 20 | I16: 46016 | J16: 9300.11 | K16: UK | L16: Net Banking | M16: 2024 | N16: 6 | O16: 0.2021060066063978 | P16: =TEXT(Table1[[#This Row],[Order_Date]],"mmm") -> Jun | Q16: =YEAR(Table1[[#This Row],[Order_Date]]) -> 2024 | R16: =Table1[[#This Row],[Profit]]/Table1[[#This Row],[Sales]] -> 0.20210601 | S16: =IF(I16<0,0,I16) -> 46016
A17: ORD017 | B17: 45294 | C17: CUST16 | D17: Phone | E17: Electronics | F17: -1 | G17: 2558 | H17: 10 | I17: -2302.2 | J17: 164.97 | K17: Canada | L17: Credit Card | M17: 2024 | N17: 1 | O17: -0.071657545 | P17: =TEXT(Table1[[#This Row],[Order_Date]],"mmm") -> Jan | Q17: =YEAR(Table1[[#This Row],[Order_Date]]) -> 2024 | R17: =Table1[[#This Row],[Profit]]/Table1[[#This Row],[Sales]] -> -0.071657545 | S17: =IF(I17<0,0,I17) -> 0
A18: ORD018 | B18: 45402 | C18: CUST14 | D18: Keyboard | E18: Accessories | F18: 4 | G18: 12978 | H18: 0 | I18: 51912 | J18: -3178.45 | K18: India | L18: UPI | M18: 2024 | N18: 4 | O18: -0.061227654 | P18: =TEXT(Table1[[#This Row],[Order_Date]],"mmm") -> Apr | Q18: =YEAR(Table1[[#This Row],[Order_Date]]) -> 2024 | R18: =Table1[[#This Row],[Profit]]/Table1[[#This Row],[Sales]] -> -0.061227654 | S18: =IF(I18<0,0,I18) -> 51912
A19: ORD019 | B19: 45429 | C19: CUST14 | D19: Keyboard | E19: Accessories | F19: 3 | G19: 7661 | H19: 5 | I19: 21833.85 | J19: -510.13 | K19: India | L19: Net Banking | M19: 2024 | N19: 5 | O19: -0.02336418 | P19: =TEXT(Table1[[#This Row],[Order_Date]],"mmm") -> May | Q19: =YEAR(Table1[[#This Row],[Order_Date]]) -> 2024 | R19: =Table1[[#This Row],[Profit]]/Table1[[#This Row],[Sales]] -> -0.02336418 | S19: =IF(I19<0,0,I19) -> 21833.85
A20: ORD020 | B20: 45315 | C20: CUST8 | D20: Monitor | E20: Electronics | F20: -1 | G20: 3815 | H20: 20 | I20: -3052 | J20: -715.42 | K20: USA | L20: Net Banking | M20: 2024 | N20: 1 | O20: 0.2344102228047182 | P20: =TEXT(Table1[[#This Row],[Order_Date]],"mmm") -> Jan | Q20: =YEAR(Table1[[#This Row],[Order_Date]]) -> 2024 | R20: =Table1[[#This Row],[Profit]]/Table1[[#This Row],[Sales]] -> 0.23441022 | S20: =IF(I20<0,0,I20) -> 0
A21: ORD021 | B21: 45507 | C21: CUST15 | D21: Laptop | E21: Electronics | F21: 0 | G21: 25336 | H21: 0 | I21: 0 | J21: 0 | K21: Canada | L21: Credit Card | M21: 2024 | N21: 8 | P21: =TEXT(Table1[[#This Row],[Order_Date]],"mmm") -> Aug | Q21: =YEAR(Table1[[#This Row],[Order_Date]]) -> 2024 | R21: =Table1[[#This Row],[Profit]]/Table1[[#This Row],[Sales]] -> #DIV/0! | S21: =IF(I21<0,0,I21) -> 0
A22: ORD022 | B22: 45430 | C22: CUST11 | D22: Phone | E22: Electronics | F22: 2 | G22: 14767 | H22: 0 | I22: 29534 | J22: 3888.8 | K22: USA | L22: UPI | M22: 2024 | N22: 5 | O22: 0.13167197128732985 | P22: =TEXT(Table1[[#This Row],[Order_Date]],"mmm") -> May | Q22: =YEAR(Table1[[#This Row],[Order_Date]]) -> 2024 | R22: =Table1[[#This Row],[Profit]]/Table1[[#This Row],[Sales]] -> 0.13167197 | S22: =IF(I22<0,0,I22) -> 29534
A23: ORD023 | B23: 45464 | C23: CUST13 | D23: Monitor | E23: Electronics | F23: -1 | G23: 12678 | H23: 0 | I23: -12678 | J23: -1749.74 | K23: USA | L23: UPI | M23: 2024 | N23: 6 | O23: 0.13801388231582268 | P23: =TEXT(Table1[[#This Row],[Order_Date]],"mmm") -> Jun | Q23: =YEAR(Table1[[#This Row],[Order_Date]]) -> 2024 | R23: =Table1[[#This Row],[Profit]]/Table1[[#This Row],[Sales]] -> 0.13801388 | S23: =IF(I23<0,0,I23) -> 0
A24: ORD024 | B24: 45372 | C24: CUST7 | D24: Monitor | E24: Electronics | F24: -1 | G24: 27974 | H24: 20 | I24: -22379.2 | J24: -2821.81 | K24: UK | L24: Net Banking | M24: 2024 | N24: 3 | O24: 0.12609074497747907 | P24: =TEXT(Table1[[#This Row],[Order_Date]],"mmm") -> Mar | Q24: =YEAR(Table1[[#This Row],[Order_Date]]) -> 2024 | R24: =Table1[[#This Row],[Profit]]/Table1[[#This Row],[Sales]] -> 0.12609074 | S24: =IF(I24<0,0,I24) -> 0
A25: ORD026 | B25: 45354 | C25: CUST6 | D25: Monitor | E25: Electronics | F25: 2 | G25: 9180 | H25: 10 | I25: 16524 | J25: 4169.76 | K25: UK | L25: UPI | M25: 2024 | N25: 3 | O25: 0.25234567901234567 | P25: =TEXT(Table1[[#This Row],[Order_Date]],"mmm") -> Mar | Q25: =YEAR(Table1[[#This Row],[Order_Date]]) -> 2024 | R25: =Table1[[#This Row],[Profit]]/Table1[[#This Row],[Sales]] -> 0.25234568 | S25: =IF(I25<0,0,I25) -> 16524
A26: ORD027 | B26: 45384 | C26: CUST4 | D26: Mouse | E26: Accessories | F26: 2 | G26: 43975 | H26: 0 | I26: 87950 | J26: 24236.56 | K26: UK | L26: Credit Card | M26: 2024 | N26: 4 | O26: 0.2755720295622513 | P26: =TEXT(Table1[[#This Row],[Order_Date]],"mmm") -> Apr | Q26: =YEAR(Table1[[#This Row],[Order_Date]]) -> 2024 | R26: =Table1[[#This Row],[Profit]]/Table1[[#This Row],[Sales]] -> 0.27557203 | S26: =IF(I26<0,0,I26) -> 87950
A27: ORD028 | B27: 45415 | C27: CUST2 | D27: Mouse | E27: Accessories | F27: 3 | G27: 13842 | H27: 10 | I27: 37373.4 | J27: 3818.2 | K27: UK | L27: UPI | M27: 2024 | N27: 5 | O27: 0.10216357088196416 | P27: =TEXT(Table1[[#This Row],[Order_Date]],"mmm") -> May | Q27: =YEAR(Table1[[#This Row],[Order_Date]]) -> 2024 | R27: =Table1[[#This Row],[Profit]]/Table1[[#This Row],[Sales]] -> 0.10216357 | S27: =IF(I27<0,0,I27) -> 37373.4
A28: ORD029 | B28: 45405 | C28: CUST14 | D28: Laptop | E28: Electronics | F28: 3 | G28: 9073 | H28: 10 | I28: 24497.1 | J28: -866.39 | K28: USA | L28: UPI | M28: 2024 | N28: 4 | O28: -0.035367043 | P28: =TEXT(Table1[[#This Row],[Order_Date]],"mmm") -> Apr | Q28: =YEAR(Table1[[#This Row],[Order_Date]]) -> 2024 | R28: =Table1[[#This Row],[Profit]]/Table1[[#This Row],[Sales]] -> -0.035367043 | S28: =IF(I28<0,0,I28) -> 24497.1
A29: ORD030 | B29: 45355 | C29: CUST2 | D29: Headphones | E29: Accessories | F29: 0 | G29: 28666 | H29: 5 | I29: 0 | J29: 0 | K29: USA | L29: UPI | M29: 2024 | N29: 3 | P29: =TEXT(Table1[[#This Row],[Order_Date]],"mmm") -> Mar | Q29: =YEAR(Table1[[#This Row],[Order_Date]]) -> 2024 | R29: =Table1[[#This Row],[Profit]]/Table1[[#This Row],[Sales]] -> #DIV/0! | S29: =IF(I29<0,0,I29) -> 0
A30: ORD031 | B30: 45294 | C30: CUST6 | D30: Headphones | E30: Accessories | F30: 1 | G30: 41175 | H30: 5 | I30: 156465 | J30: 42293.35 | K30: UK | L30: Net Banking | M30: 2024 | N30: 1 | O30: 0.27030549963250566 | P30: =TEXT(Table1[[#This Row],[Order_Date]],"mmm") -> Jan | Q30: =YEAR(Table1[[#This Row],[Order_Date]]) -> 2024 | R30: =Table1[[#This Row],[Profit]]/Table1[[#This Row],[Sales]] -> 0.2703055 | S30: =IF(I30<0,0,I30) -> 156465
A31: ORD032 | B31: 45319 | C31: CUST2 | D31: Mouse | E31: Accessories | F31: 1 | G31: 17985 | H31: 5 | I31: 17085.75 | J31: 3672.58 | K31: Canada | L31: Debit Card | M31: 2024 | N31: 1 | O31: 0.21494988513819996 | P31: =TEXT(Table1[[#This Row],[Order_Date]],"mmm") -> Jan | Q31: =YEAR(Table1[[#This Row],[Order_Date]]) -> 2024 | R31: =Table1[[#This Row],[Profit]]/Table1[[#This Row],[Sales]] -> 0.21494989 | S31: =IF(I31<0,0,I31) -> 17085.75
A32: ORD033 | B32: 45630 | C32: CUST3 | D32: Headphones | E32: Accessories | F32: 1 | G32: 15109 | H32: 0 | I32: 15109 | J32: 2478.08 | K32: Canada | L32: Debit Card | M32: 2024 | N32: 12 | O32: 0.16401350188629293 | P32: =TEXT(Table1[[#This Row],[Order_Date]],"mmm") -> Dec | Q32: =YEAR(Table1[[#This Row],[Order_Date]]) -> 2024 | R32: =Table1[[#This Row],[Profit]]/Table1[[#This Row],[Sales]] -> 0.1640135 | S32: =IF(I32<0,0,I32) -> 15109
A33: ORD035 | B33: 45627 | C33: CUST1 | D33: Monitor | E33: Electronics | F33: -1 | G33: 25744 | H33: 20 | I33: -20595.2 | J33: 493.64 | K33: USA | L33: Debit Card | M33: 2024 | N33: 12 | O33: -0.023968692 | P33: =TEXT(Table1[[#This Row],[Order_Date]],"mmm") -> Dec | Q33: =YEAR(Table1[[#This Row],[Order_Date]]) -> 2024 | R33: =Table1[[#This Row],[Profit]]/Table1[[#This Row],[Sales]] -> -0.023968692 | S33: =IF(I33<0,0,I33) -> 0
A34: ORD036 | B34: 45461 | C34: CUST10 | D34: Keyboard | E34: Accessories | F34: -1 | G34: 44031 | H34: 10 | I34: -39627.9 | J34: -5914.95 | K34: UK | L34: Net Banking | M34: 2024 | N34: 6 | O34: 0.14926226219406025 | P34: =TEXT(Table1[[#This Row],[Order_Date]],"mmm") -> Jun | Q34: =YEAR(Table1[[#This Row],[Order_Date]]) -> 2024 | R34: =Table1[[#This Row],[Profit]]/Table1[[#This Row],[Sales]] -> 0.14926226 | S34: =IF(I34<0,0,I34) -> 0
A35: ORD037 | B35: 45462 | C35: CUST6 | D35: Mouse | E35: Accessories | F35: 2 | G35: 36833 | H35: 5 | I35: 69982.7 | J35: -1628.07 | K35: India | L35: Debit Card | M35: 2024 | N35: 6 | O35: -0.023263892 | P35: =TEXT(Table1[[#This Row],[Order_Date]],"mmm") -> Jun | Q35: =YEAR(Table1[[#This Row],[Order_Date]]) -> 2024 | R35: =Table1[[#This Row],[Profit]]/Table1[[#This Row],[Sales]] -> -0.023263892 | S35: =IF(I35<0,0,I35) -> 69982.7
A36: ORD038 | B36: 45374 | C36: CUST15 | D36: Headphones | E36: Accessories | F36: 1 | G36: 28673 | H36: 20 | I36: 22938.4 | J36: 3272.5 | K36: USA | L36: UPI | M36: 2024 | N36: 3 | O36: 0.14266470198444528 | P36: =TEXT(Table1[[#This Row],[Order_Date]],"mmm") -> Mar | Q36: =YEAR(Table1[[#This Row],[Order_Date]]) -> 2024 | R36: =Table1[[#This Row],[Profit]]/Table1[[#This Row],[Sales]] -> 0.1426647 | S36: =IF(I36<0,0,I36) -> 22938.4
A37: ORD039 | B37: 45349 | C37: CUST5 | D37: Headphones | E37: Electronics | F37: 3 | G37: 6620 | H37: 5 | I37: 18867 | J37: 3190.75 | K37: Canada | L37: UPI | M37: 2024 | N37: 2 | O37: 0.1691180367838024 | P37: =TEXT(Table1[[#This Row],[Order_Date]],"mmm") -> Feb | Q37: =YEAR(Table1[[#This Row],[Order_Date]]) -> 2024 | R37: =Table1[[#This Row],[Profit]]/Table1[[#This Row],[Sales]] -> 0.16911804 | S37: =IF(I37<0,0,I37) -> 18867
A38: ORD040 | B38: 45470 | C38: CUST13 | D38: Keyboard | E38: Accessories | F38: 4 | G38: 41772 | H38: 20 | I38: 133670.4 | J38: -2970.95 | K38: India | L38: UPI | M38: 2024 | N38: 6 | O38: -0.022225938 | P38: =TEXT(Table1[[#This Row],[Order_Date]],"mmm") -> Jun | Q38: =YEAR(Table1[[#This Row],[Order_Date]]) -> 2024 | R38: =Table1[[#This Row],[Profit]]/Table1[[#This Row],[Sales]] -> -0.022225938 | S38: =IF(I38<0,0,I38) -> 133670.4
A39: ORD041 | B39: 45434 | C39: CUST4 | D39: Keyboard | E39: Accessories | F39: 1 | G39: 12026 | H39: 20 | I39: 9620.8 | J39: 825.66 | K39: UK | L39: Net Banking | M39: 2024 | N39: 5 | O39: 0.085820306 | P39: =TEXT(Table1[[#This Row],[Order_Date]],"mmm") -> May | Q39: =YEAR(Table1[[#This Row],[Order_Date]]) -> 2024 | R39: =Table1[[#This Row],[Profit]]/Table1[[#This Row],[Sales]] -> 0.085820306 | S39: =IF(I39<0,0,I39) -> 9620.8
A40: ORD042 | B40: 45296 | C40: CUST8 | D40: Monitor | E40: Electronics | F40: 4 | G40: 36405 | H40: 15 | I40: 123777 | J40: 32043.79 | K40: Canada | L40: Credit Card | M40: 2024 | N40: 1 | O40: 0.2588832335571229 | P40: =TEXT(Table1[[#This Row],[Order_Date]],"mmm") -> Jan | Q40: =YEAR(Table1[[#This Row],[Order_Date]]) -> 2024 | R40: =Table1[[#This Row],[Profit]]/Table1[[#This Row],[Sales]] -> 0.25888323 | S40: =IF(I40<0,0,I40) -> 123777
...

Sheet Analysis
A1: Total Revenue | B1: Total Orders | C1: Total Profit | D1: Average Order Value | E1: Month | F1: Sum of Net Sales Column | H1: Customer_ID | I1: Sum of Net Sales Column | L1: Country | M1: Sum of Net Sales Column | P1: Category | Q1: Count of Profit % Column
A2: =SUM(Cleaned_Data!J:J) -> 350288.71 | B2: =COUNTA(Cleaned_Data!A:A) -> 92 | C2: =SUM(Cleaned_Data!J:J) -> 350288.71 | D2: =A2/B2 -> 3807.486 | E2: Jan | F2: 1032762.4 | H2: CUST13 | I2: 858423 | L2: Canada | M2: 956588.65 | P2: Accessories | Q2: 50
E3: Feb | F3: 331925.4 | H3: CUST10 | I3: 589678.4 | L3: India | M3: 1021791.2 | P3: Electronics | Q3: 41
E4: Mar | F4: 389816.3 | H4: CUST16 | I4: 538009.9 | L4: UK | M4: 1338248.8 | P4: Grand Total | Q4: 91
E5: Apr | F5: 391150.3 | H5: CUST14 | I5: 419234.85 | L5: USA | M5: 812391.9
E6: May | F6: 447512.9 | H6: CUST18 | I6: 366994.1 | L6: Grand Total | M6: 4129020.5
E7: Jun | F7: 1234960.9 | H7: CUST6 | I7: 348493.05
E8: Aug | F8: 0 | H8: CUST8 | I8: 241900.9
E9: Oct | F9: 205348.5 | H9: CUST4 | I9: 209632.7
E10: Nov | F10: 80434.8 | H10: CUST1 | I10: 129399.3
E11: Dec | F11: 15109 | H11: CUST2 | I11: 116673
E12: Grand Total | F12: 4129020.5 | H12: Grand Total | I12: 3818439.2

Sheet Dashboard
K1: E-Commerce Sales Performance Dashboard
B4: Total Revenue | D4: Total Orders | F4: Total Profit | H4: Average Order Value
B5: =Analysis!A2 -> 350288.71 | D5: =Analysis!B2 -> 92 | F5: =Analysis!C2 -> 350288.71 | H5: =Analysis!D2 -> 3807.486
